<?xml version="1.0" ?>
<!-- =================================================================================== -->
<!-- |    This document was autogenerated by xacro from robot.xacro                    | -->
<!-- |    EDITING THIS FILE BY HAND IS NOT RECOMMENDED                                 | -->
<!-- =================================================================================== -->
<robot name="rover_platform ">
  <!-- 
    <xacro:include filename="colors.xacro" />
    <xacro:include filename="link_joints_def.xacro" /> -->
  <!-- <xacro:include filename="rover.gazebo-fortress.xacro" /> -->
  <material name="light_grey">
    <color rgba="0.4 0.4 0.4 1.0"/>
  </material>
  <material name="yellow">
    <color rgba="0.95 0.816 0.082 1.0"/>
  </material>
  <material name="black">
    <color rgba="0.15 0.15 0.15 1.0"/>
  </material>
  <material name="dark_grey">
    <color rgba="0.2 0.2 0.2 1.0"/>
  </material>
  <material name="white">
    <color rgba="0.9 0.9 0.9 1.0"/>
  </material>
  <material name="red">
    <color rgba="0.9 0.0 0.0 1.0"/>
  </material>
  <link name="rover_platform/base_link"/>
  <joint name="base_link_joint" type="fixed">
    <origin rpy="0 0 0" xyz="0 0 0.025"/>
    <parent link="rover_platform/base_link"/>
    <child link="chassis_link"/>
  </joint>
  <link name="chassis_link">
    <inertial>
      <origin rpy="0 0 0" xyz="0 0 0"/>
      <mass value="100"/>
      <inertia ixx="4.833333333333333" ixy="0" ixz="0" iyy="15.937500000000002" iyz="0" izz="15.937500000000002"/>
    </inertial>
    <visual>
      <origin rpy="0 0 0" xyz="0 0 -0.1"/>
      <geometry>
        <mesh filename="package://rover_description/meshes/rover_platform/visuals/chassis.stl"/>
        <!-- <box size="${chassis_length} ${chassis_width} ${chassis_height}" /> -->
      </geometry>
      <material name="yellow">
        <color rgba="0.15 0.15 0.15 1.0"/>
      </material>
    </visual>
    <collision>
      <origin rpy="0 0 0" xyz="0 0 -0.1"/>
      <geometry>
        <mesh filename="package://rover_description/meshes/rover_platform/visuals/chassis-collision.stl"/>
        <!-- <box size="${chassis_length} ${chassis_width} ${chassis_height}" /> -->
      </geometry>
    </collision>
  </link>
  <link name="imu_link"/>
  <joint name="imu_link_joint" type="fixed">
    <origin rpy="0 0 0" xyz="0 0 0"/>
    <parent link="chassis_link"/>
    <child link="imu_link"/>
  </joint>
  <link name="front_left_wheel_link">
    <inertial>
      <origin rpy="0 0 0" xyz="0 0 0"/>
      <mass value="15"/>
      <inertia ixx="0.01" ixy="0" ixz="0" iyy="0.01" iyz="0" izz="0.01"/>
    </inertial>
    <visual>
      <origin rpy="0 0 1.5707963267948966" xyz="0 0 0"/>
      <geometry>
        <!-- <cylinder radius="${wheel_radius}" length="${wheel_width}" /> -->
        <mesh filename="package://rover_description/meshes/rover_platform/visuals/wheel.stl"/>
      </geometry>
      <material name="dark_grey">
        <color rgba="0.2 0.2 0.2 1.0"/>
      </material>
    </visual>
    <collision>
      <origin rpy="0 0 1.5707963267948966" xyz="0 0 0"/>
      <geometry>
        <cylinder length="0.25" radius="0.3"/>
      </geometry>
    </collision>
  </link>
  <joint name="front_left_wheel_joint" type="continuous">
    <parent link="chassis_link"/>
    <child link="front_left_wheel_link"/>
    <origin rpy="0 0 0" xyz="0.5 0.5 -0.05"/>
    <axis xyz="0 1 0"/>
  </joint>
  <link name="front_right_wheel_link">
    <inertial>
      <origin rpy="0 0 0" xyz="0 0 0"/>
      <mass value="15"/>
      <inertia ixx="0.01" ixy="0" ixz="0" iyy="0.01" iyz="0" izz="0.01"/>
    </inertial>
    <visual>
      <origin rpy="0 0 1.5707963267948966" xyz="0 0 0"/>
      <geometry>
        <!-- <cylinder radius="${wheel_radius}" length="${wheel_width}" /> -->
        <mesh filename="package://rover_description/meshes/rover_platform/visuals/wheel.stl"/>
      </geometry>
      <material name="dark_grey">
        <color rgba="0.2 0.2 0.2 1.0"/>
      </material>
    </visual>
    <collision>
      <origin rpy="0 0 1.5707963267948966" xyz="0 0 0"/>
      <geometry>
        <cylinder length="0.25" radius="0.3"/>
      </geometry>
    </collision>
  </link>
  <joint name="front_right_wheel_joint" type="continuous">
    <parent link="chassis_link"/>
    <child link="front_right_wheel_link"/>
    <origin rpy="0 0 0" xyz="0.5 -0.5 -0.05"/>
    <axis xyz="0 1 0"/>
  </joint>
  <link name="rear_left_wheel_link">
    <inertial>
      <origin rpy="0 0 0" xyz="0 0 0"/>
      <mass value="15"/>
      <inertia ixx="0.01" ixy="0" ixz="0" iyy="0.01" iyz="0" izz="0.01"/>
    </inertial>
    <visual>
      <origin rpy="0 0 1.5707963267948966" xyz="0 0 0"/>
      <geometry>
        <!-- <cylinder radius="${wheel_radius}" length="${wheel_width}" /> -->
        <mesh filename="package://rover_description/meshes/rover_platform/visuals/wheel.stl"/>
      </geometry>
      <material name="dark_grey">
        <color rgba="0.2 0.2 0.2 1.0"/>
      </material>
    </visual>
    <collision>
      <origin rpy="0 0 1.5707963267948966" xyz="0 0 0"/>
      <geometry>
        <cylinder length="0.25" radius="0.3"/>
      </geometry>
    </collision>
  </link>
  <joint name="rear_left_wheel_joint" type="continuous">
    <parent link="chassis_link"/>
    <child link="rear_left_wheel_link"/>
    <origin rpy="0 0 0" xyz="-0.5 0.5 -0.05"/>
    <axis xyz="0 1 0"/>
  </joint>
  <link name="rear_right_wheel_link">
    <inertial>
      <origin rpy="0 0 0" xyz="0 0 0"/>
      <mass value="15"/>
      <inertia ixx="0.01" ixy="0" ixz="0" iyy="0.01" iyz="0" izz="0.01"/>
    </inertial>
    <visual>
      <origin rpy="0 0 1.5707963267948966" xyz="0 0 0"/>
      <geometry>
        <!-- <cylinder radius="${wheel_radius}" length="${wheel_width}" /> -->
        <mesh filename="package://rover_description/meshes/rover_platform/visuals/wheel.stl"/>
      </geometry>
      <material name="dark_grey">
        <color rgba="0.2 0.2 0.2 1.0"/>
      </material>
    </visual>
    <collision>
      <origin rpy="0 0 1.5707963267948966" xyz="0 0 0"/>
      <geometry>
        <cylinder length="0.25" radius="0.3"/>
      </geometry>
    </collision>
  </link>
  <joint name="rear_right_wheel_joint" type="continuous">
    <parent link="chassis_link"/>
    <child link="rear_right_wheel_link"/>
    <origin rpy="0 0 0" xyz="-0.5 -0.5 -0.05"/>
    <axis xyz="0 1 0"/>
  </joint>
<plugin filename="gz-sim-diff-drive-system" name="gz::sim::systems::DiffDrive">
    <!-- Wheel Information -->
    <left_joint>front_left_wheel_joint</left_joint>
    <left_joint>rear_left_wheel_joint</left_joint>
    <right_joint>front_right_wheel_joint</right_joint>
    <right_joint>rear_right_wheel_joint</right_joint>
    <wheel_radius>0.305</wheel_radius>
    <wheel_separation>1.386</wheel_separation>
    <max_linear_acceleration>1.0</max_linear_acceleration>
    <!-- Input -->
    <topic>cmd_vel</topic>
    <!-- Output -->
    <odometry_frame>odom</odometry_frame> <!-- Ensure no prefix here -->
    <robot_base_frame>base_link</robot_base_frame> <!-- Ensure no prefix here -->
    <publish_odom>true</publish_odom>
    <publish_odom_tf>true</publish_odom_tf>
    <publish_wheel_tf>true</publish_wheel_tf>
    <odom_topic>odom</odom_topic>
    <odom_publisher_frequency>50</odom_publisher_frequency>
    <tf_topic>/tf</tf_topic>
</plugin>

  <!-- Add Accessories -->
  <!-- <xacro:include filename="accessories.urdf.xacro" />      -->
</robot>
